<?xml version="1.0" ?>
<!-- =================================================================================== -->
<!-- |    This document was autogenerated by xacro from /home/vim3/myros/11-simulation/simulation_ws/src/dongbot_description/urdf/dongbot/dongbot.urdf.xacro | -->
<!-- |    EDITING THIS FILE BY HAND IS NOT RECOMMENDED                                 | -->
<!-- =================================================================================== -->
<robot name="dongbot">
  <!-- 底板 添加一个虚拟部件-->
  <link name="base_footprint"/>
  <link name="base_link">
    <!-- 部件的外观描述 -->
    <visual>
      <!-- 沿着自己几何中心的偏移 和旋转量 -->
      <origin rpy="0 0 0" xyz="0 0 0"/>
      <!-- 几何形状 -->
      <geometry>
        <!-- 圆柱体 radius 半径 0.10m 高度 length 0.12m -->
        <cylinder length="0.12" radius="0.1"/>
      </geometry>
      <!-- 材质颜色 -->
      <material name="white">
        <color rgba="1 1 1 0.5"/>
      </material>
    </visual>
    <collision>
      <!-- 沿着自己几何中心的偏移 和旋转量 -->
      <origin rpy="0 0 0" xyz="0 0 0"/>
      <!-- 几何形状 -->
      <geometry>
        <!-- 圆柱体 radius 半径 0.10m 高度 length 0.12m -->
        <cylinder length="0.12" radius="0.1"/>
      </geometry>
      <!-- 材质颜色 -->
      <material name="white">
        <color rgba="1 1 1 0.5"/>
      </material>
    </collision>
    <inertial>
      <mass value="1.0"/>
      <inertia ixx="0.0037000000000000006" ixy="0" ixz="0" iyy="0.0037000000000000006" iyz="0" izz="0.005000000000000001"/>
    </inertial>
  </link>
  <joint name="joint_name" type="fixed">
    <origin rpy="0 0 0" xyz="0 0 0.091"/>
    <parent link="base_footprint"/>
    <child link="base_link"/>
  </joint>
  <!-- IMU惯性测量单元 -->
  <link name="imu_link">
    <!-- 部件的外观描述 -->
    <visual>
      <!-- 沿着自己几何中心的偏移 和旋转量 -->
      <origin rpy="0 0 0" xyz="0 0 0"/>
      <!-- 几何形状 -->
      <geometry>
        <!-- 长方体 长宽高者为2cm -->
        <box size="0.02 0.02 0.02"/>
      </geometry>
      <!-- 材质颜色 -->
      <material name="black">
        <color rgba="0 0 0 1"/>
      </material>
    </visual>
    <collision>
      <!-- 沿着自己几何中心的偏移 和旋转量 -->
      <origin rpy="0 0 0" xyz="0 0 0"/>
      <!-- 几何形状 -->
      <geometry>
        <!-- 长方体 长宽高者为2cm -->
        <box size="0.02 0.02 0.02"/>
      </geometry>
      <!-- 材质颜色 -->
      <material name="black">
        <color rgba="0 0 0 1"/>
      </material>
    </collision>
    <inertial>
      <mass value="0.05"/>
      <inertia ixx="3.3333333333333333e-06" ixy="0.0" ixz="0.0" iyy="3.3333333333333333e-06" iyz="0.0" izz="3.3333333333333333e-06"/>
    </inertial>
  </link>
  <!-- 机器人的关节，用于组合机器人的部件 -->
  <joint name="imu_joint" type="fixed">
    <parent link="base_link"/>
    <child link="imu_link"/>
    <origin rpy="0.0 0.0 0.0" xyz="0.0 0.0 0.02"/>
  </joint>
  <!-- 相机 -->
  <link name="camera_link">
    <!-- 部件的外观描述 -->
    <visual>
      <!-- 沿着自己几何中心的偏移 和旋转量 -->
      <origin rpy="0 0 0" xyz="0 0 0"/>
      <!-- 几何形状 -->
      <geometry>
        <!-- 长方体 长宽高者为2cm -->
        <box size="0.02 0.10 0.02"/>
      </geometry>
      <!-- 材质颜色 -->
      <material name="cyan">
        <color rgba="0 1 1 1"/>
      </material>
    </visual>
    <collision>
      <!-- 沿着自己几何中心的偏移 和旋转量 -->
      <origin rpy="0 0 0" xyz="0 0 0"/>
      <!-- 几何形状 -->
      <geometry>
        <!-- 长方体 长宽高者为2cm -->
        <box size="0.02 0.10 0.02"/>
      </geometry>
      <!-- 材质颜色 -->
      <material name="cyan">
        <color rgba="0 1 1 1"/>
      </material>
    </collision>
    <inertial>
      <mass value="0.05"/>
      <inertia ixx="4.333333333333334e-05" ixy="0.0" ixz="0.0" iyy="3.3333333333333333e-06" iyz="0.0" izz="4.333333333333334e-05"/>
    </inertial>
  </link>
  <link name="camera_optical_link"/>
  <!-- 机器人的关节，用于组合机器人的部件 -->
  <joint name="camera_joint" type="fixed">
    <parent link="base_link"/>
    <child link="camera_link"/>
    <origin rpy="0.0 0.0 0.0" xyz="0.1 0.0 0.075"/>
  </joint>
  <!-- 机器人的关节，用于组合机器人的部件 -->
  <joint name="camera_optical_joint" type="fixed">
    <parent link="camera_link"/>
    <child link="camera_optical_link"/>
    <origin rpy="-1.5707963267948966 0.0 -1.5707963267948966" xyz="0 0 0"/>
  </joint>
  <!-- 激光雷达支撑杆 -->
  <link name="laser_cylinder_link">
    <!-- 部件的外观描述 -->
    <visual>
      <!-- 沿着自己几何中心的偏移 和旋转量 -->
      <origin rpy="0 0 0" xyz="0 0 0"/>
      <!-- 几何形状 -->
      <geometry>
        <!-- 圆柱体 半径为0.01 轴长为0.1 -->
        <cylinder length="0.1" radius="0.01"/>
      </geometry>
      <!-- 材质颜色 -->
      <material name="cyan">
        <color rgba="0 1 1 1"/>
      </material>
    </visual>
    <collision>
      <!-- 沿着自己几何中心的偏移 和旋转量 -->
      <origin rpy="0 0 0" xyz="0 0 0"/>
      <!-- 几何形状 -->
      <geometry>
        <!-- 圆柱体 半径为0.01 轴长为0.1 -->
        <cylinder length="0.1" radius="0.01"/>
      </geometry>
      <!-- 材质颜色 -->
      <material name="cyan">
        <color rgba="0 1 1 1"/>
      </material>
    </collision>
    <inertial>
      <mass value="0.05"/>
      <inertia ixx="4.2916666666666675e-05" ixy="0" ixz="0" iyy="4.2916666666666675e-05" iyz="0" izz="2.5e-06"/>
    </inertial>
  </link>
  <!-- 激光雷达 -->
  <link name="laser_link">
    <!-- 部件的外观描述 -->
    <visual>
      <!-- 沿着自己几何中心的偏移 和旋转量 -->
      <origin rpy="0 0 0" xyz="0 0 0"/>
      <!-- 几何形状 -->
      <geometry>
        <!-- 圆柱体 半径为0.02 轴长为0.02 -->
        <cylinder length="0.02" radius="0.02"/>
      </geometry>
      <!-- 材质颜色 -->
      <material name="cyan">
        <color rgba="0 1 1 1"/>
      </material>
    </visual>
    <collision>
      <!-- 沿着自己几何中心的偏移 和旋转量 -->
      <origin rpy="0 0 0" xyz="0 0 0"/>
      <!-- 几何形状 -->
      <geometry>
        <!-- 圆柱体 半径为0.02 轴长为0.02 -->
        <cylinder length="0.02" radius="0.02"/>
      </geometry>
      <!-- 材质颜色 -->
      <material name="cyan">
        <color rgba="0 1 1 1"/>
      </material>
    </collision>
    <inertial>
      <mass value="0.1"/>
      <inertia ixx="1.3333333333333332e-05" ixy="0" ixz="0" iyy="1.3333333333333332e-05" iyz="0" izz="2e-05"/>
    </inertial>
  </link>
  <!-- 固定激光雷达 -->
  <joint name="laser_joint" type="fixed">
    <parent link="laser_cylinder_link"/>
    <child link="laser_link"/>
    <origin rpy="0.0 0.0 0.0" xyz="0.0 0.0 0.05"/>
  </joint>
  <joint name="laser_cylinder_joint" type="fixed">
    <parent link="base_link"/>
    <child link="laser_cylinder_link"/>
    <origin rpy="0.0 0.0 0.0" xyz="0.0 0.0 0.11"/>
  </joint>
  <!-- 在gazebo中显示为黑色 -->
  <gazebo reference="laser_cylinder_link">
    <material>Gazebo/Black</material>
  </gazebo>
  <gazebo reference="laser_link">
    <material>Gazebo/Black</material>
  </gazebo>
  <!-- 执行器轮子单元 -->
  <link name="left_wheel_link">
    <!-- 部件的外观描述 -->
    <visual>
      <!-- 沿着自己几何中心的偏移 和旋转量 -->
      <origin rpy="1.57079 0 0" xyz="0 0 0"/>
      <!-- 几何形状 -->
      <geometry>
        <!-- 长方体 长宽高者为2cm -->
        <cylinder length="0.04" radius="0.032"/>
      </geometry>
      <!-- 材质颜色 -->
      <material name="yellow">
        <color rgba="1 1 0 0.8"/>
      </material>
    </visual>
    <collision>
      <!-- 沿着自己几何中心的偏移 和旋转量 -->
      <origin rpy="1.57079 0 0" xyz="0 0 0"/>
      <!-- 几何形状 -->
      <geometry>
        <!-- 长方体 长宽高者为2cm -->
        <cylinder length="0.04" radius="0.032"/>
      </geometry>
      <!-- 材质颜色 -->
      <material name="yellow">
        <color rgba="1 1 0 0.8"/>
      </material>
    </collision>
    <inertial>
      <mass value="0.05"/>
      <inertia ixx="1.9466666666666668e-05" ixy="0" ixz="0" iyy="1.9466666666666668e-05" iyz="0" izz="2.56e-05"/>
    </inertial>
  </link>
  <!-- 机器人的关节，用于组合机器人的部件 -->
  <joint name="left_wheel_joint" type="continuous">
    <parent link="base_link"/>
    <child link="left_wheel_link"/>
    <origin rpy="0.0 0.0 0.0" xyz="0 0.10 -0.06"/>
    <axis xyz="0 1 0"/>
  </joint>
  <gazebo reference="left_wheel_link">
    <mu1 value="20.0"/>
    <mu2 value="20.0"/>
    <kp value="1000000000.0"/>
    <kd value="1.0"/>
  </gazebo>
  <!-- 执行器轮子单元 -->
  <link name="right_wheel_link">
    <!-- 部件的外观描述 -->
    <visual>
      <!-- 沿着自己几何中心的偏移 和旋转量 -->
      <origin rpy="1.57079 0 0" xyz="0 0 0"/>
      <!-- 几何形状 -->
      <geometry>
        <!-- 长方体 长宽高者为2cm -->
        <cylinder length="0.04" radius="0.032"/>
      </geometry>
      <!-- 材质颜色 -->
      <material name="yellow">
        <color rgba="1 1 0 0.8"/>
      </material>
    </visual>
    <collision>
      <!-- 沿着自己几何中心的偏移 和旋转量 -->
      <origin rpy="1.57079 0 0" xyz="0 0 0"/>
      <!-- 几何形状 -->
      <geometry>
        <!-- 长方体 长宽高者为2cm -->
        <cylinder length="0.04" radius="0.032"/>
      </geometry>
      <!-- 材质颜色 -->
      <material name="yellow">
        <color rgba="1 1 0 0.8"/>
      </material>
    </collision>
    <inertial>
      <mass value="0.05"/>
      <inertia ixx="1.9466666666666668e-05" ixy="0" ixz="0" iyy="1.9466666666666668e-05" iyz="0" izz="2.56e-05"/>
    </inertial>
  </link>
  <!-- 机器人的关节，用于组合机器人的部件 -->
  <joint name="right_wheel_joint" type="continuous">
    <parent link="base_link"/>
    <child link="right_wheel_link"/>
    <origin rpy="0.0 0.0 0.0" xyz="0 -0.10 -0.06"/>
    <axis xyz="0 1 0"/>
  </joint>
  <gazebo reference="right_wheel_link">
    <mu1 value="20.0"/>
    <mu2 value="20.0"/>
    <kp value="1000000000.0"/>
    <kd value="1.0"/>
  </gazebo>
  <!-- 执行器轮子单元 -->
  <link name="front_wheel_link">
    <!-- 部件的外观描述 -->
    <visual>
      <!-- 沿着自己几何中心的偏移 和旋转量 -->
      <origin rpy="0 0 0" xyz="0 0 0"/>
      <!-- 几何形状 -->
      <geometry>
        <!-- 长方体 长宽高者为2cm -->
        <sphere radius="0.016"/>
      </geometry>
      <!-- 材质颜色 -->
      <material name="fuchsia">
        <color rgba="1 0 1 0.8"/>
      </material>
    </visual>
    <collision>
      <!-- 沿着自己几何中心的偏移 和旋转量 -->
      <origin rpy="0 0 0" xyz="0 0 0"/>
      <!-- 几何形状 -->
      <geometry>
        <!-- 长方体 长宽高者为2cm -->
        <sphere radius="0.016"/>
      </geometry>
      <!-- 材质颜色 -->
      <material name="fuchsia">
        <color rgba="1 0 1 0.8"/>
      </material>
    </collision>
    <inertial>
      <mass value="0.05"/>
      <inertia ixx="5.120000000000001e-06" ixy="0.0" ixz="0.0" iyy="5.120000000000001e-06" iyz="0.0" izz="5.120000000000001e-06"/>
    </inertial>
  </link>
  <!-- 机器人的关节，用于组合机器人的部件 -->
  <!-- 万向轮旋不旋转 无所谓 -->
  <joint name="front_wheel_joint" type="fixed">
    <parent link="base_link"/>
    <child link="front_wheel_link"/>
    <origin rpy="0.0 0.0 0.0" xyz="0.08 0 -0.076"/>
  </joint>
  <gazebo reference="front_wheel_link">
    <mu1 value="0.0"/>
    <mu2 value="0.0"/>
    <kp value="1000000000.0"/>
    <kd value="1.0"/>
  </gazebo>
  <!-- 执行器轮子单元 -->
  <link name="back_wheel_link">
    <!-- 部件的外观描述 -->
    <visual>
      <!-- 沿着自己几何中心的偏移 和旋转量 -->
      <origin rpy="0 0 0" xyz="0 0 0"/>
      <!-- 几何形状 -->
      <geometry>
        <!-- 长方体 长宽高者为2cm -->
        <sphere radius="0.016"/>
      </geometry>
      <!-- 材质颜色 -->
      <material name="fuchsia">
        <color rgba="1 0 1 0.8"/>
      </material>
    </visual>
    <collision>
      <!-- 沿着自己几何中心的偏移 和旋转量 -->
      <origin rpy="0 0 0" xyz="0 0 0"/>
      <!-- 几何形状 -->
      <geometry>
        <!-- 长方体 长宽高者为2cm -->
        <sphere radius="0.016"/>
      </geometry>
      <!-- 材质颜色 -->
      <material name="fuchsia">
        <color rgba="1 0 1 0.8"/>
      </material>
    </collision>
    <inertial>
      <mass value="0.05"/>
      <inertia ixx="5.120000000000001e-06" ixy="0.0" ixz="0.0" iyy="5.120000000000001e-06" iyz="0.0" izz="5.120000000000001e-06"/>
    </inertial>
  </link>
  <!-- 机器人的关节，用于组合机器人的部件 -->
  <!-- 万向轮旋不旋转 无所谓 -->
  <joint name="back_wheel_joint" type="fixed">
    <parent link="base_link"/>
    <child link="back_wheel_link"/>
    <origin rpy="0.0 0.0 0.0" xyz="-0.08 0 -0.076"/>
  </joint>
  <gazebo reference="back_wheel_link">
    <mu1 value="0.0"/>
    <mu2 value="0.0"/>
    <kp value="1000000000.0"/>
    <kd value="1.0"/>
  </gazebo>
  <gazebo>
    <plugin filename="libgazebo_ros_diff_drive.so" name="diff_drive">
      <ros>
        <namespace>/</namespace>
        <remapping>cmd_vel:=cmd_vel</remapping>
        <remapping>odom:=odom</remapping>
      </ros>
      <update_rate>30</update_rate>
      <!-- wheels -->
      <left_joint>left_wheel_joint</left_joint>
      <right_joint>right_wheel_joint</right_joint>
      <!-- kinematics -->
      <wheel_separation>0.2</wheel_separation>
      <wheel_diameter>0.064</wheel_diameter>
      <!-- limits -->
      <max_wheel_torque>20</max_wheel_torque>
      <max_wheel_acceleration>1.0</max_wheel_acceleration>
      <!-- output -->
      <publish_odom>true</publish_odom>
      <publish_odom_tf>true</publish_odom_tf>
      <publish_wheel_tf>true</publish_wheel_tf>
      <odometry_frame>odom</odometry_frame>
      <robot_base_frame>base_footprint</robot_base_frame>
    </plugin>
  </gazebo>
  <gazebo reference="laser_link">
    <sensor name="laserscan" type="ray">
      <!-- 插件的名字是一个ROS中的插件库 -->
      <plugin filename="libgazebo_ros_ray_sensor.so" name="laserscan">
        <ros>
          <namespace>/</namespace>
          <remapping>~/out:=scan</remapping>
        </ros>
        <output_type>sensor_msgs/LaserScan</output_type>
        <frame_name>laser_link</frame_name>
      </plugin>
      <always_on>true</always_on>
      <visualize>true</visualize>
      <update_rate>5</update_rate>
      <pose>0 0 0 0 0 0</pose>
      <!-- 激光传感器配置 -->
      <ray>
        <!-- 设置扫描范围 -->
        <scan>
          <horizontal>
            <samples>360</samples>
            <resolution>1.000000</resolution>
            <min_angle>0.000000</min_angle>
            <max_angle>6.280000</max_angle>
          </horizontal>
        </scan>
        <!-- 设置扫描距离 -->
        <range>
          <min>0.120000</min>
          <max>8.0</max>
          <resolution>0.015000</resolution>
        </range>
        <!-- 设置噪声 -->
        <noise>
          <type>gaussian</type>
          <mean>0.0</mean>
          <stddev>0.01</stddev>
        </noise>
      </ray>
    </sensor>
  </gazebo>
  <gazebo reference="imu_link">
    <sensor name="imu_sensor" type="imu">
      <plugin filename="libgazebo_ros_imu_sensor.so" name="imu_plugin">
        <ros>
          <namespace>/</namespace>
          <remapping>~/out:=imu</remapping>
        </ros>
        <initial_orientation_as_reference>false</initial_orientation_as_reference>
      </plugin>
      <update_rate>100</update_rate>
      <always_on>true</always_on>
      <!-- 六轴噪声设置 -->
      <imu>
        <angular_velocity>
          <x>
            <noise type="gaussian">
              <mean>0.0</mean>
              <stddev>2e-4</stddev>
              <bias_mean>0.0000075</bias_mean>
              <bias_stddev>0.0000008</bias_stddev>
            </noise>
          </x>
          <y>
            <noise type="gaussian">
              <mean>0.0</mean>
              <stddev>2e-4</stddev>
              <bias_mean>0.0000075</bias_mean>
              <bias_stddev>0.0000008</bias_stddev>
            </noise>
          </y>
          <z>
            <noise type="gaussian">
              <mean>0.0</mean>
              <stddev>2e-4</stddev>
              <bias_mean>0.0000075</bias_mean>
              <bias_stddev>0.0000008</bias_stddev>
            </noise>
          </z>
        </angular_velocity>
        <linear_acceleration>
          <x>
            <noise type="gaussian">
              <mean>0.0</mean>
              <stddev>1.7e-2</stddev>
              <bias_mean>0.1</bias_mean>
              <bias_stddev>0.001</bias_stddev>
            </noise>
          </x>
          <y>
            <noise type="gaussian">
              <mean>0.0</mean>
              <stddev>1.7e-2</stddev>
              <bias_mean>0.1</bias_mean>
              <bias_stddev>0.001</bias_stddev>
            </noise>
          </y>
          <z>
            <noise type="gaussian">
              <mean>0.0</mean>
              <stddev>1.7e-2</stddev>
              <bias_mean>0.1</bias_mean>
              <bias_stddev>0.001</bias_stddev>
            </noise>
          </z>
        </linear_acceleration>
      </imu>
    </sensor>
  </gazebo>
</robot>
